we are running from this directory: /lustre1/work/aurorasg/TNG
 the name of the job is: rotate
Th job ID is 3959554
The job was run on these nodes: compute-2-0-26
Number of nodes: 1
We are using 1 cores
We are using 1 cores per node
Total of 1 cores
Linux compute-2-0-26.foreman.hpc.ntnu.no 3.10.0-693.21.1.el7.x86_64 #1 SMP Wed Mar 7 19:03:37 UTC 2018 x86_64 x86_64 x86_64 GNU/Linux
Traceback (most recent call last):
  File "/share/apps/software/Core/Anaconda3/2018.12/lib/python3.7/site-packages/pandas/io/pickle.py", line 166, in try_read
    return read_wrapper(lambda f: pkl.load(f))
  File "/share/apps/software/Core/Anaconda3/2018.12/lib/python3.7/site-packages/pandas/io/pickle.py", line 149, in read_wrapper
    return func(f)
  File "/share/apps/software/Core/Anaconda3/2018.12/lib/python3.7/site-packages/pandas/io/pickle.py", line 166, in <lambda>
    return read_wrapper(lambda f: pkl.load(f))
ValueError: unsupported pickle protocol: 5

During handling of the above exception, another exception occurred:

Traceback (most recent call last):
  File "/share/apps/software/Core/Anaconda3/2018.12/lib/python3.7/site-packages/pandas/io/pickle.py", line 171, in try_read
    lambda f: pc.load(f, encoding=encoding, compat=False))
  File "/share/apps/software/Core/Anaconda3/2018.12/lib/python3.7/site-packages/pandas/io/pickle.py", line 149, in read_wrapper
    return func(f)
  File "/share/apps/software/Core/Anaconda3/2018.12/lib/python3.7/site-packages/pandas/io/pickle.py", line 171, in <lambda>
    lambda f: pc.load(f, encoding=encoding, compat=False))
  File "/share/apps/software/Core/Anaconda3/2018.12/lib/python3.7/site-packages/pandas/compat/pickle_compat.py", line 212, in load
    return up.load()
  File "/share/apps/software/Core/Anaconda3/2018.12/lib/python3.7/pickle.py", line 1085, in load
    dispatch[key[0]](self)
  File "/share/apps/software/Core/Anaconda3/2018.12/lib/python3.7/pickle.py", line 1104, in load_proto
    raise ValueError("unsupported pickle protocol: %d" % proto)
ValueError: unsupported pickle protocol: 5

During handling of the above exception, another exception occurred:

Traceback (most recent call last):
  File "/share/apps/software/Core/Anaconda3/2018.12/lib/python3.7/site-packages/pandas/io/pickle.py", line 177, in read_pickle
    return try_read(path)
  File "/share/apps/software/Core/Anaconda3/2018.12/lib/python3.7/site-packages/pandas/io/pickle.py", line 175, in try_read
    lambda f: pc.load(f, encoding=encoding, compat=True))
  File "/share/apps/software/Core/Anaconda3/2018.12/lib/python3.7/site-packages/pandas/io/pickle.py", line 149, in read_wrapper
    return func(f)
  File "/share/apps/software/Core/Anaconda3/2018.12/lib/python3.7/site-packages/pandas/io/pickle.py", line 175, in <lambda>
    lambda f: pc.load(f, encoding=encoding, compat=True))
  File "/share/apps/software/Core/Anaconda3/2018.12/lib/python3.7/site-packages/pandas/compat/pickle_compat.py", line 212, in load
    return up.load()
  File "/share/apps/software/Core/Anaconda3/2018.12/lib/python3.7/pickle.py", line 1085, in load
    dispatch[key[0]](self)
  File "/share/apps/software/Core/Anaconda3/2018.12/lib/python3.7/pickle.py", line 1104, in load_proto
    raise ValueError("unsupported pickle protocol: %d" % proto)
ValueError: unsupported pickle protocol: 5

During handling of the above exception, another exception occurred:

Traceback (most recent call last):
  File "/share/apps/software/Core/Anaconda3/2018.12/lib/python3.7/site-packages/pandas/io/pickle.py", line 166, in try_read
    return read_wrapper(lambda f: pkl.load(f))
  File "/share/apps/software/Core/Anaconda3/2018.12/lib/python3.7/site-packages/pandas/io/pickle.py", line 149, in read_wrapper
    return func(f)
  File "/share/apps/software/Core/Anaconda3/2018.12/lib/python3.7/site-packages/pandas/io/pickle.py", line 166, in <lambda>
    return read_wrapper(lambda f: pkl.load(f))
ValueError: unsupported pickle protocol: 5

During handling of the above exception, another exception occurred:

Traceback (most recent call last):
  File "/share/apps/software/Core/Anaconda3/2018.12/lib/python3.7/site-packages/pandas/io/pickle.py", line 171, in try_read
    lambda f: pc.load(f, encoding=encoding, compat=False))
  File "/share/apps/software/Core/Anaconda3/2018.12/lib/python3.7/site-packages/pandas/io/pickle.py", line 149, in read_wrapper
    return func(f)
  File "/share/apps/software/Core/Anaconda3/2018.12/lib/python3.7/site-packages/pandas/io/pickle.py", line 171, in <lambda>
    lambda f: pc.load(f, encoding=encoding, compat=False))
  File "/share/apps/software/Core/Anaconda3/2018.12/lib/python3.7/site-packages/pandas/compat/pickle_compat.py", line 212, in load
    return up.load()
  File "/share/apps/software/Core/Anaconda3/2018.12/lib/python3.7/pickle.py", line 1085, in load
    dispatch[key[0]](self)
  File "/share/apps/software/Core/Anaconda3/2018.12/lib/python3.7/pickle.py", line 1104, in load_proto
    raise ValueError("unsupported pickle protocol: %d" % proto)
ValueError: unsupported pickle protocol: 5

During handling of the above exception, another exception occurred:

Traceback (most recent call last):
  File "./src/check_rotation.py", line 108, in <module>
    subhalo_rotation(tng_run, test_name, 99, int(args.subhalo))
  File "./src/check_rotation.py", line 92, in subhalo_rotation
    group_cat = pd.read_pickle(new_cat_path)
  File "/share/apps/software/Core/Anaconda3/2018.12/lib/python3.7/site-packages/pandas/io/pickle.py", line 180, in read_pickle
    return try_read(path, encoding='latin1')
  File "/share/apps/software/Core/Anaconda3/2018.12/lib/python3.7/site-packages/pandas/io/pickle.py", line 175, in try_read
    lambda f: pc.load(f, encoding=encoding, compat=True))
  File "/share/apps/software/Core/Anaconda3/2018.12/lib/python3.7/site-packages/pandas/io/pickle.py", line 149, in read_wrapper
    return func(f)
  File "/share/apps/software/Core/Anaconda3/2018.12/lib/python3.7/site-packages/pandas/io/pickle.py", line 175, in <lambda>
    lambda f: pc.load(f, encoding=encoding, compat=True))
  File "/share/apps/software/Core/Anaconda3/2018.12/lib/python3.7/site-packages/pandas/compat/pickle_compat.py", line 212, in load
    return up.load()
  File "/share/apps/software/Core/Anaconda3/2018.12/lib/python3.7/pickle.py", line 1085, in load
    dispatch[key[0]](self)
  File "/share/apps/software/Core/Anaconda3/2018.12/lib/python3.7/pickle.py", line 1104, in load_proto
    raise ValueError("unsupported pickle protocol: %d" % proto)
ValueError: unsupported pickle protocol: 5
Traceback (most recent call last):
  File "/share/apps/software/Core/Anaconda3/2018.12/lib/python3.7/site-packages/pandas/io/pickle.py", line 166, in try_read
    return read_wrapper(lambda f: pkl.load(f))
  File "/share/apps/software/Core/Anaconda3/2018.12/lib/python3.7/site-packages/pandas/io/pickle.py", line 149, in read_wrapper
    return func(f)
  File "/share/apps/software/Core/Anaconda3/2018.12/lib/python3.7/site-packages/pandas/io/pickle.py", line 166, in <lambda>
    return read_wrapper(lambda f: pkl.load(f))
ValueError: unsupported pickle protocol: 5

During handling of the above exception, another exception occurred:

Traceback (most recent call last):
  File "/share/apps/software/Core/Anaconda3/2018.12/lib/python3.7/site-packages/pandas/io/pickle.py", line 171, in try_read
    lambda f: pc.load(f, encoding=encoding, compat=False))
  File "/share/apps/software/Core/Anaconda3/2018.12/lib/python3.7/site-packages/pandas/io/pickle.py", line 149, in read_wrapper
    return func(f)
  File "/share/apps/software/Core/Anaconda3/2018.12/lib/python3.7/site-packages/pandas/io/pickle.py", line 171, in <lambda>
    lambda f: pc.load(f, encoding=encoding, compat=False))
  File "/share/apps/software/Core/Anaconda3/2018.12/lib/python3.7/site-packages/pandas/compat/pickle_compat.py", line 212, in load
    return up.load()
  File "/share/apps/software/Core/Anaconda3/2018.12/lib/python3.7/pickle.py", line 1085, in load
    dispatch[key[0]](self)
  File "/share/apps/software/Core/Anaconda3/2018.12/lib/python3.7/pickle.py", line 1104, in load_proto
    raise ValueError("unsupported pickle protocol: %d" % proto)
ValueError: unsupported pickle protocol: 5

During handling of the above exception, another exception occurred:

Traceback (most recent call last):
  File "/share/apps/software/Core/Anaconda3/2018.12/lib/python3.7/site-packages/pandas/io/pickle.py", line 177, in read_pickle
    return try_read(path)
  File "/share/apps/software/Core/Anaconda3/2018.12/lib/python3.7/site-packages/pandas/io/pickle.py", line 175, in try_read
    lambda f: pc.load(f, encoding=encoding, compat=True))
  File "/share/apps/software/Core/Anaconda3/2018.12/lib/python3.7/site-packages/pandas/io/pickle.py", line 149, in read_wrapper
    return func(f)
  File "/share/apps/software/Core/Anaconda3/2018.12/lib/python3.7/site-packages/pandas/io/pickle.py", line 175, in <lambda>
    lambda f: pc.load(f, encoding=encoding, compat=True))
  File "/share/apps/software/Core/Anaconda3/2018.12/lib/python3.7/site-packages/pandas/compat/pickle_compat.py", line 212, in load
    return up.load()
  File "/share/apps/software/Core/Anaconda3/2018.12/lib/python3.7/pickle.py", line 1085, in load
    dispatch[key[0]](self)
  File "/share/apps/software/Core/Anaconda3/2018.12/lib/python3.7/pickle.py", line 1104, in load_proto
    raise ValueError("unsupported pickle protocol: %d" % proto)
ValueError: unsupported pickle protocol: 5

During handling of the above exception, another exception occurred:

Traceback (most recent call last):
  File "/share/apps/software/Core/Anaconda3/2018.12/lib/python3.7/site-packages/pandas/io/pickle.py", line 166, in try_read
    return read_wrapper(lambda f: pkl.load(f))
  File "/share/apps/software/Core/Anaconda3/2018.12/lib/python3.7/site-packages/pandas/io/pickle.py", line 149, in read_wrapper
    return func(f)
  File "/share/apps/software/Core/Anaconda3/2018.12/lib/python3.7/site-packages/pandas/io/pickle.py", line 166, in <lambda>
    return read_wrapper(lambda f: pkl.load(f))
ValueError: unsupported pickle protocol: 5

During handling of the above exception, another exception occurred:

Traceback (most recent call last):
  File "/share/apps/software/Core/Anaconda3/2018.12/lib/python3.7/site-packages/pandas/io/pickle.py", line 171, in try_read
    lambda f: pc.load(f, encoding=encoding, compat=False))
  File "/share/apps/software/Core/Anaconda3/2018.12/lib/python3.7/site-packages/pandas/io/pickle.py", line 149, in read_wrapper
    return func(f)
  File "/share/apps/software/Core/Anaconda3/2018.12/lib/python3.7/site-packages/pandas/io/pickle.py", line 171, in <lambda>
    lambda f: pc.load(f, encoding=encoding, compat=False))
  File "/share/apps/software/Core/Anaconda3/2018.12/lib/python3.7/site-packages/pandas/compat/pickle_compat.py", line 212, in load
    return up.load()
  File "/share/apps/software/Core/Anaconda3/2018.12/lib/python3.7/pickle.py", line 1085, in load
    dispatch[key[0]](self)
  File "/share/apps/software/Core/Anaconda3/2018.12/lib/python3.7/pickle.py", line 1104, in load_proto
    raise ValueError("unsupported pickle protocol: %d" % proto)
ValueError: unsupported pickle protocol: 5

During handling of the above exception, another exception occurred:

Traceback (most recent call last):
  File "./src/check_rotation.py", line 108, in <module>
    subhalo_rotation(tng_run, test_name, 99, int(args.subhalo))
  File "./src/check_rotation.py", line 92, in subhalo_rotation
    group_cat = pd.read_pickle(new_cat_path)
  File "/share/apps/software/Core/Anaconda3/2018.12/lib/python3.7/site-packages/pandas/io/pickle.py", line 180, in read_pickle
    return try_read(path, encoding='latin1')
  File "/share/apps/software/Core/Anaconda3/2018.12/lib/python3.7/site-packages/pandas/io/pickle.py", line 175, in try_read
    lambda f: pc.load(f, encoding=encoding, compat=True))
  File "/share/apps/software/Core/Anaconda3/2018.12/lib/python3.7/site-packages/pandas/io/pickle.py", line 149, in read_wrapper
    return func(f)
  File "/share/apps/software/Core/Anaconda3/2018.12/lib/python3.7/site-packages/pandas/io/pickle.py", line 175, in <lambda>
    lambda f: pc.load(f, encoding=encoding, compat=True))
  File "/share/apps/software/Core/Anaconda3/2018.12/lib/python3.7/site-packages/pandas/compat/pickle_compat.py", line 212, in load
    return up.load()
  File "/share/apps/software/Core/Anaconda3/2018.12/lib/python3.7/pickle.py", line 1085, in load
    dispatch[key[0]](self)
  File "/share/apps/software/Core/Anaconda3/2018.12/lib/python3.7/pickle.py", line 1104, in load_proto
    raise ValueError("unsupported pickle protocol: %d" % proto)
ValueError: unsupported pickle protocol: 5
Traceback (most recent call last):
  File "/share/apps/software/Core/Anaconda3/2018.12/lib/python3.7/site-packages/pandas/io/pickle.py", line 166, in try_read
    return read_wrapper(lambda f: pkl.load(f))
  File "/share/apps/software/Core/Anaconda3/2018.12/lib/python3.7/site-packages/pandas/io/pickle.py", line 149, in read_wrapper
    return func(f)
  File "/share/apps/software/Core/Anaconda3/2018.12/lib/python3.7/site-packages/pandas/io/pickle.py", line 166, in <lambda>
    return read_wrapper(lambda f: pkl.load(f))
ValueError: unsupported pickle protocol: 5

During handling of the above exception, another exception occurred:

Traceback (most recent call last):
  File "/share/apps/software/Core/Anaconda3/2018.12/lib/python3.7/site-packages/pandas/io/pickle.py", line 171, in try_read
    lambda f: pc.load(f, encoding=encoding, compat=False))
  File "/share/apps/software/Core/Anaconda3/2018.12/lib/python3.7/site-packages/pandas/io/pickle.py", line 149, in read_wrapper
    return func(f)
  File "/share/apps/software/Core/Anaconda3/2018.12/lib/python3.7/site-packages/pandas/io/pickle.py", line 171, in <lambda>
    lambda f: pc.load(f, encoding=encoding, compat=False))
  File "/share/apps/software/Core/Anaconda3/2018.12/lib/python3.7/site-packages/pandas/compat/pickle_compat.py", line 212, in load
    return up.load()
  File "/share/apps/software/Core/Anaconda3/2018.12/lib/python3.7/pickle.py", line 1085, in load
    dispatch[key[0]](self)
  File "/share/apps/software/Core/Anaconda3/2018.12/lib/python3.7/pickle.py", line 1104, in load_proto
    raise ValueError("unsupported pickle protocol: %d" % proto)
ValueError: unsupported pickle protocol: 5

During handling of the above exception, another exception occurred:

Traceback (most recent call last):
  File "/share/apps/software/Core/Anaconda3/2018.12/lib/python3.7/site-packages/pandas/io/pickle.py", line 177, in read_pickle
    return try_read(path)
  File "/share/apps/software/Core/Anaconda3/2018.12/lib/python3.7/site-packages/pandas/io/pickle.py", line 175, in try_read
    lambda f: pc.load(f, encoding=encoding, compat=True))
  File "/share/apps/software/Core/Anaconda3/2018.12/lib/python3.7/site-packages/pandas/io/pickle.py", line 149, in read_wrapper
    return func(f)
  File "/share/apps/software/Core/Anaconda3/2018.12/lib/python3.7/site-packages/pandas/io/pickle.py", line 175, in <lambda>
    lambda f: pc.load(f, encoding=encoding, compat=True))
  File "/share/apps/software/Core/Anaconda3/2018.12/lib/python3.7/site-packages/pandas/compat/pickle_compat.py", line 212, in load
    return up.load()
  File "/share/apps/software/Core/Anaconda3/2018.12/lib/python3.7/pickle.py", line 1085, in load
    dispatch[key[0]](self)
  File "/share/apps/software/Core/Anaconda3/2018.12/lib/python3.7/pickle.py", line 1104, in load_proto
    raise ValueError("unsupported pickle protocol: %d" % proto)
ValueError: unsupported pickle protocol: 5

During handling of the above exception, another exception occurred:

Traceback (most recent call last):
  File "/share/apps/software/Core/Anaconda3/2018.12/lib/python3.7/site-packages/pandas/io/pickle.py", line 166, in try_read
    return read_wrapper(lambda f: pkl.load(f))
  File "/share/apps/software/Core/Anaconda3/2018.12/lib/python3.7/site-packages/pandas/io/pickle.py", line 149, in read_wrapper
    return func(f)
  File "/share/apps/software/Core/Anaconda3/2018.12/lib/python3.7/site-packages/pandas/io/pickle.py", line 166, in <lambda>
    return read_wrapper(lambda f: pkl.load(f))
ValueError: unsupported pickle protocol: 5

During handling of the above exception, another exception occurred:

Traceback (most recent call last):
  File "/share/apps/software/Core/Anaconda3/2018.12/lib/python3.7/site-packages/pandas/io/pickle.py", line 171, in try_read
    lambda f: pc.load(f, encoding=encoding, compat=False))
  File "/share/apps/software/Core/Anaconda3/2018.12/lib/python3.7/site-packages/pandas/io/pickle.py", line 149, in read_wrapper
    return func(f)
  File "/share/apps/software/Core/Anaconda3/2018.12/lib/python3.7/site-packages/pandas/io/pickle.py", line 171, in <lambda>
    lambda f: pc.load(f, encoding=encoding, compat=False))
  File "/share/apps/software/Core/Anaconda3/2018.12/lib/python3.7/site-packages/pandas/compat/pickle_compat.py", line 212, in load
    return up.load()
  File "/share/apps/software/Core/Anaconda3/2018.12/lib/python3.7/pickle.py", line 1085, in load
    dispatch[key[0]](self)
  File "/share/apps/software/Core/Anaconda3/2018.12/lib/python3.7/pickle.py", line 1104, in load_proto
    raise ValueError("unsupported pickle protocol: %d" % proto)
ValueError: unsupported pickle protocol: 5

During handling of the above exception, another exception occurred:

Traceback (most recent call last):
  File "./src/check_rotation.py", line 108, in <module>
    subhalo_rotation(tng_run, test_name, 99, int(args.subhalo))
  File "./src/check_rotation.py", line 92, in subhalo_rotation
    group_cat = pd.read_pickle(new_cat_path)
  File "/share/apps/software/Core/Anaconda3/2018.12/lib/python3.7/site-packages/pandas/io/pickle.py", line 180, in read_pickle
    return try_read(path, encoding='latin1')
  File "/share/apps/software/Core/Anaconda3/2018.12/lib/python3.7/site-packages/pandas/io/pickle.py", line 175, in try_read
    lambda f: pc.load(f, encoding=encoding, compat=True))
  File "/share/apps/software/Core/Anaconda3/2018.12/lib/python3.7/site-packages/pandas/io/pickle.py", line 149, in read_wrapper
    return func(f)
  File "/share/apps/software/Core/Anaconda3/2018.12/lib/python3.7/site-packages/pandas/io/pickle.py", line 175, in <lambda>
    lambda f: pc.load(f, encoding=encoding, compat=True))
  File "/share/apps/software/Core/Anaconda3/2018.12/lib/python3.7/site-packages/pandas/compat/pickle_compat.py", line 212, in load
    return up.load()
  File "/share/apps/software/Core/Anaconda3/2018.12/lib/python3.7/pickle.py", line 1085, in load
    dispatch[key[0]](self)
  File "/share/apps/software/Core/Anaconda3/2018.12/lib/python3.7/pickle.py", line 1104, in load_proto
    raise ValueError("unsupported pickle protocol: %d" % proto)
ValueError: unsupported pickle protocol: 5
Traceback (most recent call last):
  File "/share/apps/software/Core/Anaconda3/2018.12/lib/python3.7/site-packages/pandas/io/pickle.py", line 166, in try_read
    return read_wrapper(lambda f: pkl.load(f))
  File "/share/apps/software/Core/Anaconda3/2018.12/lib/python3.7/site-packages/pandas/io/pickle.py", line 149, in read_wrapper
    return func(f)
  File "/share/apps/software/Core/Anaconda3/2018.12/lib/python3.7/site-packages/pandas/io/pickle.py", line 166, in <lambda>
    return read_wrapper(lambda f: pkl.load(f))
ValueError: unsupported pickle protocol: 5

During handling of the above exception, another exception occurred:

Traceback (most recent call last):
  File "/share/apps/software/Core/Anaconda3/2018.12/lib/python3.7/site-packages/pandas/io/pickle.py", line 171, in try_read
    lambda f: pc.load(f, encoding=encoding, compat=False))
  File "/share/apps/software/Core/Anaconda3/2018.12/lib/python3.7/site-packages/pandas/io/pickle.py", line 149, in read_wrapper
    return func(f)
  File "/share/apps/software/Core/Anaconda3/2018.12/lib/python3.7/site-packages/pandas/io/pickle.py", line 171, in <lambda>
    lambda f: pc.load(f, encoding=encoding, compat=False))
  File "/share/apps/software/Core/Anaconda3/2018.12/lib/python3.7/site-packages/pandas/compat/pickle_compat.py", line 212, in load
    return up.load()
  File "/share/apps/software/Core/Anaconda3/2018.12/lib/python3.7/pickle.py", line 1085, in load
    dispatch[key[0]](self)
  File "/share/apps/software/Core/Anaconda3/2018.12/lib/python3.7/pickle.py", line 1104, in load_proto
    raise ValueError("unsupported pickle protocol: %d" % proto)
ValueError: unsupported pickle protocol: 5

During handling of the above exception, another exception occurred:

Traceback (most recent call last):
  File "/share/apps/software/Core/Anaconda3/2018.12/lib/python3.7/site-packages/pandas/io/pickle.py", line 177, in read_pickle
    return try_read(path)
  File "/share/apps/software/Core/Anaconda3/2018.12/lib/python3.7/site-packages/pandas/io/pickle.py", line 175, in try_read
    lambda f: pc.load(f, encoding=encoding, compat=True))
  File "/share/apps/software/Core/Anaconda3/2018.12/lib/python3.7/site-packages/pandas/io/pickle.py", line 149, in read_wrapper
    return func(f)
  File "/share/apps/software/Core/Anaconda3/2018.12/lib/python3.7/site-packages/pandas/io/pickle.py", line 175, in <lambda>
    lambda f: pc.load(f, encoding=encoding, compat=True))
  File "/share/apps/software/Core/Anaconda3/2018.12/lib/python3.7/site-packages/pandas/compat/pickle_compat.py", line 212, in load
    return up.load()
  File "/share/apps/software/Core/Anaconda3/2018.12/lib/python3.7/pickle.py", line 1085, in load
    dispatch[key[0]](self)
  File "/share/apps/software/Core/Anaconda3/2018.12/lib/python3.7/pickle.py", line 1104, in load_proto
    raise ValueError("unsupported pickle protocol: %d" % proto)
ValueError: unsupported pickle protocol: 5

During handling of the above exception, another exception occurred:

Traceback (most recent call last):
  File "/share/apps/software/Core/Anaconda3/2018.12/lib/python3.7/site-packages/pandas/io/pickle.py", line 166, in try_read
    return read_wrapper(lambda f: pkl.load(f))
  File "/share/apps/software/Core/Anaconda3/2018.12/lib/python3.7/site-packages/pandas/io/pickle.py", line 149, in read_wrapper
    return func(f)
  File "/share/apps/software/Core/Anaconda3/2018.12/lib/python3.7/site-packages/pandas/io/pickle.py", line 166, in <lambda>
    return read_wrapper(lambda f: pkl.load(f))
ValueError: unsupported pickle protocol: 5

During handling of the above exception, another exception occurred:

Traceback (most recent call last):
  File "/share/apps/software/Core/Anaconda3/2018.12/lib/python3.7/site-packages/pandas/io/pickle.py", line 171, in try_read
    lambda f: pc.load(f, encoding=encoding, compat=False))
  File "/share/apps/software/Core/Anaconda3/2018.12/lib/python3.7/site-packages/pandas/io/pickle.py", line 149, in read_wrapper
    return func(f)
  File "/share/apps/software/Core/Anaconda3/2018.12/lib/python3.7/site-packages/pandas/io/pickle.py", line 171, in <lambda>
    lambda f: pc.load(f, encoding=encoding, compat=False))
  File "/share/apps/software/Core/Anaconda3/2018.12/lib/python3.7/site-packages/pandas/compat/pickle_compat.py", line 212, in load
    return up.load()
  File "/share/apps/software/Core/Anaconda3/2018.12/lib/python3.7/pickle.py", line 1085, in load
    dispatch[key[0]](self)
  File "/share/apps/software/Core/Anaconda3/2018.12/lib/python3.7/pickle.py", line 1104, in load_proto
    raise ValueError("unsupported pickle protocol: %d" % proto)
ValueError: unsupported pickle protocol: 5

During handling of the above exception, another exception occurred:

Traceback (most recent call last):
  File "./src/check_rotation.py", line 108, in <module>
    subhalo_rotation(tng_run, test_name, 99, int(args.subhalo))
  File "./src/check_rotation.py", line 92, in subhalo_rotation
    group_cat = pd.read_pickle(new_cat_path)
  File "/share/apps/software/Core/Anaconda3/2018.12/lib/python3.7/site-packages/pandas/io/pickle.py", line 180, in read_pickle
    return try_read(path, encoding='latin1')
  File "/share/apps/software/Core/Anaconda3/2018.12/lib/python3.7/site-packages/pandas/io/pickle.py", line 175, in try_read
    lambda f: pc.load(f, encoding=encoding, compat=True))
  File "/share/apps/software/Core/Anaconda3/2018.12/lib/python3.7/site-packages/pandas/io/pickle.py", line 149, in read_wrapper
    return func(f)
  File "/share/apps/software/Core/Anaconda3/2018.12/lib/python3.7/site-packages/pandas/io/pickle.py", line 175, in <lambda>
    lambda f: pc.load(f, encoding=encoding, compat=True))
  File "/share/apps/software/Core/Anaconda3/2018.12/lib/python3.7/site-packages/pandas/compat/pickle_compat.py", line 212, in load
    return up.load()
  File "/share/apps/software/Core/Anaconda3/2018.12/lib/python3.7/pickle.py", line 1085, in load
    dispatch[key[0]](self)
  File "/share/apps/software/Core/Anaconda3/2018.12/lib/python3.7/pickle.py", line 1104, in load_proto
    raise ValueError("unsupported pickle protocol: %d" % proto)
ValueError: unsupported pickle protocol: 5
Traceback (most recent call last):
  File "/share/apps/software/Core/Anaconda3/2018.12/lib/python3.7/site-packages/pandas/io/pickle.py", line 166, in try_read
    return read_wrapper(lambda f: pkl.load(f))
  File "/share/apps/software/Core/Anaconda3/2018.12/lib/python3.7/site-packages/pandas/io/pickle.py", line 149, in read_wrapper
    return func(f)
  File "/share/apps/software/Core/Anaconda3/2018.12/lib/python3.7/site-packages/pandas/io/pickle.py", line 166, in <lambda>
    return read_wrapper(lambda f: pkl.load(f))
ValueError: unsupported pickle protocol: 5

During handling of the above exception, another exception occurred:

Traceback (most recent call last):
  File "/share/apps/software/Core/Anaconda3/2018.12/lib/python3.7/site-packages/pandas/io/pickle.py", line 171, in try_read
    lambda f: pc.load(f, encoding=encoding, compat=False))
  File "/share/apps/software/Core/Anaconda3/2018.12/lib/python3.7/site-packages/pandas/io/pickle.py", line 149, in read_wrapper
    return func(f)
  File "/share/apps/software/Core/Anaconda3/2018.12/lib/python3.7/site-packages/pandas/io/pickle.py", line 171, in <lambda>
    lambda f: pc.load(f, encoding=encoding, compat=False))
  File "/share/apps/software/Core/Anaconda3/2018.12/lib/python3.7/site-packages/pandas/compat/pickle_compat.py", line 212, in load
    return up.load()
  File "/share/apps/software/Core/Anaconda3/2018.12/lib/python3.7/pickle.py", line 1085, in load
    dispatch[key[0]](self)
  File "/share/apps/software/Core/Anaconda3/2018.12/lib/python3.7/pickle.py", line 1104, in load_proto
    raise ValueError("unsupported pickle protocol: %d" % proto)
ValueError: unsupported pickle protocol: 5

During handling of the above exception, another exception occurred:

Traceback (most recent call last):
  File "/share/apps/software/Core/Anaconda3/2018.12/lib/python3.7/site-packages/pandas/io/pickle.py", line 177, in read_pickle
    return try_read(path)
  File "/share/apps/software/Core/Anaconda3/2018.12/lib/python3.7/site-packages/pandas/io/pickle.py", line 175, in try_read
    lambda f: pc.load(f, encoding=encoding, compat=True))
  File "/share/apps/software/Core/Anaconda3/2018.12/lib/python3.7/site-packages/pandas/io/pickle.py", line 149, in read_wrapper
    return func(f)
  File "/share/apps/software/Core/Anaconda3/2018.12/lib/python3.7/site-packages/pandas/io/pickle.py", line 175, in <lambda>
    lambda f: pc.load(f, encoding=encoding, compat=True))
  File "/share/apps/software/Core/Anaconda3/2018.12/lib/python3.7/site-packages/pandas/compat/pickle_compat.py", line 212, in load
    return up.load()
  File "/share/apps/software/Core/Anaconda3/2018.12/lib/python3.7/pickle.py", line 1085, in load
    dispatch[key[0]](self)
  File "/share/apps/software/Core/Anaconda3/2018.12/lib/python3.7/pickle.py", line 1104, in load_proto
    raise ValueError("unsupported pickle protocol: %d" % proto)
ValueError: unsupported pickle protocol: 5

During handling of the above exception, another exception occurred:

Traceback (most recent call last):
  File "/share/apps/software/Core/Anaconda3/2018.12/lib/python3.7/site-packages/pandas/io/pickle.py", line 166, in try_read
    return read_wrapper(lambda f: pkl.load(f))
  File "/share/apps/software/Core/Anaconda3/2018.12/lib/python3.7/site-packages/pandas/io/pickle.py", line 149, in read_wrapper
    return func(f)
  File "/share/apps/software/Core/Anaconda3/2018.12/lib/python3.7/site-packages/pandas/io/pickle.py", line 166, in <lambda>
    return read_wrapper(lambda f: pkl.load(f))
ValueError: unsupported pickle protocol: 5

During handling of the above exception, another exception occurred:

Traceback (most recent call last):
  File "/share/apps/software/Core/Anaconda3/2018.12/lib/python3.7/site-packages/pandas/io/pickle.py", line 171, in try_read
    lambda f: pc.load(f, encoding=encoding, compat=False))
  File "/share/apps/software/Core/Anaconda3/2018.12/lib/python3.7/site-packages/pandas/io/pickle.py", line 149, in read_wrapper
    return func(f)
  File "/share/apps/software/Core/Anaconda3/2018.12/lib/python3.7/site-packages/pandas/io/pickle.py", line 171, in <lambda>
    lambda f: pc.load(f, encoding=encoding, compat=False))
  File "/share/apps/software/Core/Anaconda3/2018.12/lib/python3.7/site-packages/pandas/compat/pickle_compat.py", line 212, in load
    return up.load()
  File "/share/apps/software/Core/Anaconda3/2018.12/lib/python3.7/pickle.py", line 1085, in load
    dispatch[key[0]](self)
  File "/share/apps/software/Core/Anaconda3/2018.12/lib/python3.7/pickle.py", line 1104, in load_proto
    raise ValueError("unsupported pickle protocol: %d" % proto)
ValueError: unsupported pickle protocol: 5

During handling of the above exception, another exception occurred:

Traceback (most recent call last):
  File "./src/check_rotation.py", line 108, in <module>
    subhalo_rotation(tng_run, test_name, 99, int(args.subhalo))
  File "./src/check_rotation.py", line 92, in subhalo_rotation
    group_cat = pd.read_pickle(new_cat_path)
  File "/share/apps/software/Core/Anaconda3/2018.12/lib/python3.7/site-packages/pandas/io/pickle.py", line 180, in read_pickle
    return try_read(path, encoding='latin1')
  File "/share/apps/software/Core/Anaconda3/2018.12/lib/python3.7/site-packages/pandas/io/pickle.py", line 175, in try_read
    lambda f: pc.load(f, encoding=encoding, compat=True))
  File "/share/apps/software/Core/Anaconda3/2018.12/lib/python3.7/site-packages/pandas/io/pickle.py", line 149, in read_wrapper
    return func(f)
  File "/share/apps/software/Core/Anaconda3/2018.12/lib/python3.7/site-packages/pandas/io/pickle.py", line 175, in <lambda>
    lambda f: pc.load(f, encoding=encoding, compat=True))
  File "/share/apps/software/Core/Anaconda3/2018.12/lib/python3.7/site-packages/pandas/compat/pickle_compat.py", line 212, in load
    return up.load()
  File "/share/apps/software/Core/Anaconda3/2018.12/lib/python3.7/pickle.py", line 1085, in load
    dispatch[key[0]](self)
  File "/share/apps/software/Core/Anaconda3/2018.12/lib/python3.7/pickle.py", line 1104, in load_proto
    raise ValueError("unsupported pickle protocol: %d" % proto)
ValueError: unsupported pickle protocol: 5
Traceback (most recent call last):
  File "/share/apps/software/Core/Anaconda3/2018.12/lib/python3.7/site-packages/pandas/io/pickle.py", line 166, in try_read
    return read_wrapper(lambda f: pkl.load(f))
  File "/share/apps/software/Core/Anaconda3/2018.12/lib/python3.7/site-packages/pandas/io/pickle.py", line 149, in read_wrapper
    return func(f)
  File "/share/apps/software/Core/Anaconda3/2018.12/lib/python3.7/site-packages/pandas/io/pickle.py", line 166, in <lambda>
    return read_wrapper(lambda f: pkl.load(f))
ValueError: unsupported pickle protocol: 5

During handling of the above exception, another exception occurred:

Traceback (most recent call last):
  File "/share/apps/software/Core/Anaconda3/2018.12/lib/python3.7/site-packages/pandas/io/pickle.py", line 171, in try_read
    lambda f: pc.load(f, encoding=encoding, compat=False))
  File "/share/apps/software/Core/Anaconda3/2018.12/lib/python3.7/site-packages/pandas/io/pickle.py", line 149, in read_wrapper
    return func(f)
  File "/share/apps/software/Core/Anaconda3/2018.12/lib/python3.7/site-packages/pandas/io/pickle.py", line 171, in <lambda>
    lambda f: pc.load(f, encoding=encoding, compat=False))
  File "/share/apps/software/Core/Anaconda3/2018.12/lib/python3.7/site-packages/pandas/compat/pickle_compat.py", line 212, in load
    return up.load()
  File "/share/apps/software/Core/Anaconda3/2018.12/lib/python3.7/pickle.py", line 1085, in load
    dispatch[key[0]](self)
  File "/share/apps/software/Core/Anaconda3/2018.12/lib/python3.7/pickle.py", line 1104, in load_proto
    raise ValueError("unsupported pickle protocol: %d" % proto)
ValueError: unsupported pickle protocol: 5

During handling of the above exception, another exception occurred:

Traceback (most recent call last):
  File "/share/apps/software/Core/Anaconda3/2018.12/lib/python3.7/site-packages/pandas/io/pickle.py", line 177, in read_pickle
    return try_read(path)
  File "/share/apps/software/Core/Anaconda3/2018.12/lib/python3.7/site-packages/pandas/io/pickle.py", line 175, in try_read
    lambda f: pc.load(f, encoding=encoding, compat=True))
  File "/share/apps/software/Core/Anaconda3/2018.12/lib/python3.7/site-packages/pandas/io/pickle.py", line 149, in read_wrapper
    return func(f)
  File "/share/apps/software/Core/Anaconda3/2018.12/lib/python3.7/site-packages/pandas/io/pickle.py", line 175, in <lambda>
    lambda f: pc.load(f, encoding=encoding, compat=True))
  File "/share/apps/software/Core/Anaconda3/2018.12/lib/python3.7/site-packages/pandas/compat/pickle_compat.py", line 212, in load
    return up.load()
  File "/share/apps/software/Core/Anaconda3/2018.12/lib/python3.7/pickle.py", line 1085, in load
    dispatch[key[0]](self)
  File "/share/apps/software/Core/Anaconda3/2018.12/lib/python3.7/pickle.py", line 1104, in load_proto
    raise ValueError("unsupported pickle protocol: %d" % proto)
ValueError: unsupported pickle protocol: 5

During handling of the above exception, another exception occurred:

Traceback (most recent call last):
  File "/share/apps/software/Core/Anaconda3/2018.12/lib/python3.7/site-packages/pandas/io/pickle.py", line 166, in try_read
    return read_wrapper(lambda f: pkl.load(f))
  File "/share/apps/software/Core/Anaconda3/2018.12/lib/python3.7/site-packages/pandas/io/pickle.py", line 149, in read_wrapper
    return func(f)
  File "/share/apps/software/Core/Anaconda3/2018.12/lib/python3.7/site-packages/pandas/io/pickle.py", line 166, in <lambda>
    return read_wrapper(lambda f: pkl.load(f))
ValueError: unsupported pickle protocol: 5

During handling of the above exception, another exception occurred:

Traceback (most recent call last):
  File "/share/apps/software/Core/Anaconda3/2018.12/lib/python3.7/site-packages/pandas/io/pickle.py", line 171, in try_read
    lambda f: pc.load(f, encoding=encoding, compat=False))
  File "/share/apps/software/Core/Anaconda3/2018.12/lib/python3.7/site-packages/pandas/io/pickle.py", line 149, in read_wrapper
    return func(f)
  File "/share/apps/software/Core/Anaconda3/2018.12/lib/python3.7/site-packages/pandas/io/pickle.py", line 171, in <lambda>
    lambda f: pc.load(f, encoding=encoding, compat=False))
  File "/share/apps/software/Core/Anaconda3/2018.12/lib/python3.7/site-packages/pandas/compat/pickle_compat.py", line 212, in load
    return up.load()
  File "/share/apps/software/Core/Anaconda3/2018.12/lib/python3.7/pickle.py", line 1085, in load
    dispatch[key[0]](self)
  File "/share/apps/software/Core/Anaconda3/2018.12/lib/python3.7/pickle.py", line 1104, in load_proto
    raise ValueError("unsupported pickle protocol: %d" % proto)
ValueError: unsupported pickle protocol: 5

During handling of the above exception, another exception occurred:

Traceback (most recent call last):
  File "./src/check_rotation.py", line 108, in <module>
    subhalo_rotation(tng_run, test_name, 99, int(args.subhalo))
  File "./src/check_rotation.py", line 92, in subhalo_rotation
    group_cat = pd.read_pickle(new_cat_path)
  File "/share/apps/software/Core/Anaconda3/2018.12/lib/python3.7/site-packages/pandas/io/pickle.py", line 180, in read_pickle
    return try_read(path, encoding='latin1')
  File "/share/apps/software/Core/Anaconda3/2018.12/lib/python3.7/site-packages/pandas/io/pickle.py", line 175, in try_read
    lambda f: pc.load(f, encoding=encoding, compat=True))
  File "/share/apps/software/Core/Anaconda3/2018.12/lib/python3.7/site-packages/pandas/io/pickle.py", line 149, in read_wrapper
    return func(f)
  File "/share/apps/software/Core/Anaconda3/2018.12/lib/python3.7/site-packages/pandas/io/pickle.py", line 175, in <lambda>
    lambda f: pc.load(f, encoding=encoding, compat=True))
  File "/share/apps/software/Core/Anaconda3/2018.12/lib/python3.7/site-packages/pandas/compat/pickle_compat.py", line 212, in load
    return up.load()
  File "/share/apps/software/Core/Anaconda3/2018.12/lib/python3.7/pickle.py", line 1085, in load
    dispatch[key[0]](self)
  File "/share/apps/software/Core/Anaconda3/2018.12/lib/python3.7/pickle.py", line 1104, in load_proto
    raise ValueError("unsupported pickle protocol: %d" % proto)
ValueError: unsupported pickle protocol: 5
Traceback (most recent call last):
  File "/share/apps/software/Core/Anaconda3/2018.12/lib/python3.7/site-packages/pandas/io/pickle.py", line 166, in try_read
    return read_wrapper(lambda f: pkl.load(f))
  File "/share/apps/software/Core/Anaconda3/2018.12/lib/python3.7/site-packages/pandas/io/pickle.py", line 149, in read_wrapper
    return func(f)
  File "/share/apps/software/Core/Anaconda3/2018.12/lib/python3.7/site-packages/pandas/io/pickle.py", line 166, in <lambda>
    return read_wrapper(lambda f: pkl.load(f))
ValueError: unsupported pickle protocol: 5

During handling of the above exception, another exception occurred:

Traceback (most recent call last):
  File "/share/apps/software/Core/Anaconda3/2018.12/lib/python3.7/site-packages/pandas/io/pickle.py", line 171, in try_read
    lambda f: pc.load(f, encoding=encoding, compat=False))
  File "/share/apps/software/Core/Anaconda3/2018.12/lib/python3.7/site-packages/pandas/io/pickle.py", line 149, in read_wrapper
    return func(f)
  File "/share/apps/software/Core/Anaconda3/2018.12/lib/python3.7/site-packages/pandas/io/pickle.py", line 171, in <lambda>
    lambda f: pc.load(f, encoding=encoding, compat=False))
  File "/share/apps/software/Core/Anaconda3/2018.12/lib/python3.7/site-packages/pandas/compat/pickle_compat.py", line 212, in load
    return up.load()
  File "/share/apps/software/Core/Anaconda3/2018.12/lib/python3.7/pickle.py", line 1085, in load
    dispatch[key[0]](self)
  File "/share/apps/software/Core/Anaconda3/2018.12/lib/python3.7/pickle.py", line 1104, in load_proto
    raise ValueError("unsupported pickle protocol: %d" % proto)
ValueError: unsupported pickle protocol: 5

During handling of the above exception, another exception occurred:

Traceback (most recent call last):
  File "/share/apps/software/Core/Anaconda3/2018.12/lib/python3.7/site-packages/pandas/io/pickle.py", line 177, in read_pickle
    return try_read(path)
  File "/share/apps/software/Core/Anaconda3/2018.12/lib/python3.7/site-packages/pandas/io/pickle.py", line 175, in try_read
    lambda f: pc.load(f, encoding=encoding, compat=True))
  File "/share/apps/software/Core/Anaconda3/2018.12/lib/python3.7/site-packages/pandas/io/pickle.py", line 149, in read_wrapper
    return func(f)
  File "/share/apps/software/Core/Anaconda3/2018.12/lib/python3.7/site-packages/pandas/io/pickle.py", line 175, in <lambda>
    lambda f: pc.load(f, encoding=encoding, compat=True))
  File "/share/apps/software/Core/Anaconda3/2018.12/lib/python3.7/site-packages/pandas/compat/pickle_compat.py", line 212, in load
    return up.load()
  File "/share/apps/software/Core/Anaconda3/2018.12/lib/python3.7/pickle.py", line 1085, in load
    dispatch[key[0]](self)
  File "/share/apps/software/Core/Anaconda3/2018.12/lib/python3.7/pickle.py", line 1104, in load_proto
    raise ValueError("unsupported pickle protocol: %d" % proto)
ValueError: unsupported pickle protocol: 5

During handling of the above exception, another exception occurred:

Traceback (most recent call last):
  File "/share/apps/software/Core/Anaconda3/2018.12/lib/python3.7/site-packages/pandas/io/pickle.py", line 166, in try_read
    return read_wrapper(lambda f: pkl.load(f))
  File "/share/apps/software/Core/Anaconda3/2018.12/lib/python3.7/site-packages/pandas/io/pickle.py", line 149, in read_wrapper
    return func(f)
  File "/share/apps/software/Core/Anaconda3/2018.12/lib/python3.7/site-packages/pandas/io/pickle.py", line 166, in <lambda>
    return read_wrapper(lambda f: pkl.load(f))
ValueError: unsupported pickle protocol: 5

During handling of the above exception, another exception occurred:

Traceback (most recent call last):
  File "/share/apps/software/Core/Anaconda3/2018.12/lib/python3.7/site-packages/pandas/io/pickle.py", line 171, in try_read
    lambda f: pc.load(f, encoding=encoding, compat=False))
  File "/share/apps/software/Core/Anaconda3/2018.12/lib/python3.7/site-packages/pandas/io/pickle.py", line 149, in read_wrapper
    return func(f)
  File "/share/apps/software/Core/Anaconda3/2018.12/lib/python3.7/site-packages/pandas/io/pickle.py", line 171, in <lambda>
    lambda f: pc.load(f, encoding=encoding, compat=False))
  File "/share/apps/software/Core/Anaconda3/2018.12/lib/python3.7/site-packages/pandas/compat/pickle_compat.py", line 212, in load
    return up.load()
  File "/share/apps/software/Core/Anaconda3/2018.12/lib/python3.7/pickle.py", line 1085, in load
    dispatch[key[0]](self)
  File "/share/apps/software/Core/Anaconda3/2018.12/lib/python3.7/pickle.py", line 1104, in load_proto
    raise ValueError("unsupported pickle protocol: %d" % proto)
ValueError: unsupported pickle protocol: 5

During handling of the above exception, another exception occurred:

Traceback (most recent call last):
  File "./src/check_rotation.py", line 108, in <module>
    subhalo_rotation(tng_run, test_name, 99, int(args.subhalo))
  File "./src/check_rotation.py", line 92, in subhalo_rotation
    group_cat = pd.read_pickle(new_cat_path)
  File "/share/apps/software/Core/Anaconda3/2018.12/lib/python3.7/site-packages/pandas/io/pickle.py", line 180, in read_pickle
    return try_read(path, encoding='latin1')
  File "/share/apps/software/Core/Anaconda3/2018.12/lib/python3.7/site-packages/pandas/io/pickle.py", line 175, in try_read
    lambda f: pc.load(f, encoding=encoding, compat=True))
  File "/share/apps/software/Core/Anaconda3/2018.12/lib/python3.7/site-packages/pandas/io/pickle.py", line 149, in read_wrapper
    return func(f)
  File "/share/apps/software/Core/Anaconda3/2018.12/lib/python3.7/site-packages/pandas/io/pickle.py", line 175, in <lambda>
    lambda f: pc.load(f, encoding=encoding, compat=True))
  File "/share/apps/software/Core/Anaconda3/2018.12/lib/python3.7/site-packages/pandas/compat/pickle_compat.py", line 212, in load
    return up.load()
  File "/share/apps/software/Core/Anaconda3/2018.12/lib/python3.7/pickle.py", line 1085, in load
    dispatch[key[0]](self)
  File "/share/apps/software/Core/Anaconda3/2018.12/lib/python3.7/pickle.py", line 1104, in load_proto
    raise ValueError("unsupported pickle protocol: %d" % proto)
ValueError: unsupported pickle protocol: 5
Traceback (most recent call last):
  File "/share/apps/software/Core/Anaconda3/2018.12/lib/python3.7/site-packages/pandas/io/pickle.py", line 166, in try_read
    return read_wrapper(lambda f: pkl.load(f))
  File "/share/apps/software/Core/Anaconda3/2018.12/lib/python3.7/site-packages/pandas/io/pickle.py", line 149, in read_wrapper
    return func(f)
  File "/share/apps/software/Core/Anaconda3/2018.12/lib/python3.7/site-packages/pandas/io/pickle.py", line 166, in <lambda>
    return read_wrapper(lambda f: pkl.load(f))
ValueError: unsupported pickle protocol: 5

During handling of the above exception, another exception occurred:

Traceback (most recent call last):
  File "/share/apps/software/Core/Anaconda3/2018.12/lib/python3.7/site-packages/pandas/io/pickle.py", line 171, in try_read
    lambda f: pc.load(f, encoding=encoding, compat=False))
  File "/share/apps/software/Core/Anaconda3/2018.12/lib/python3.7/site-packages/pandas/io/pickle.py", line 149, in read_wrapper
    return func(f)
  File "/share/apps/software/Core/Anaconda3/2018.12/lib/python3.7/site-packages/pandas/io/pickle.py", line 171, in <lambda>
    lambda f: pc.load(f, encoding=encoding, compat=False))
  File "/share/apps/software/Core/Anaconda3/2018.12/lib/python3.7/site-packages/pandas/compat/pickle_compat.py", line 212, in load
    return up.load()
  File "/share/apps/software/Core/Anaconda3/2018.12/lib/python3.7/pickle.py", line 1085, in load
    dispatch[key[0]](self)
  File "/share/apps/software/Core/Anaconda3/2018.12/lib/python3.7/pickle.py", line 1104, in load_proto
    raise ValueError("unsupported pickle protocol: %d" % proto)
ValueError: unsupported pickle protocol: 5

During handling of the above exception, another exception occurred:

Traceback (most recent call last):
  File "/share/apps/software/Core/Anaconda3/2018.12/lib/python3.7/site-packages/pandas/io/pickle.py", line 177, in read_pickle
    return try_read(path)
  File "/share/apps/software/Core/Anaconda3/2018.12/lib/python3.7/site-packages/pandas/io/pickle.py", line 175, in try_read
    lambda f: pc.load(f, encoding=encoding, compat=True))
  File "/share/apps/software/Core/Anaconda3/2018.12/lib/python3.7/site-packages/pandas/io/pickle.py", line 149, in read_wrapper
    return func(f)
  File "/share/apps/software/Core/Anaconda3/2018.12/lib/python3.7/site-packages/pandas/io/pickle.py", line 175, in <lambda>
    lambda f: pc.load(f, encoding=encoding, compat=True))
  File "/share/apps/software/Core/Anaconda3/2018.12/lib/python3.7/site-packages/pandas/compat/pickle_compat.py", line 212, in load
    return up.load()
  File "/share/apps/software/Core/Anaconda3/2018.12/lib/python3.7/pickle.py", line 1085, in load
    dispatch[key[0]](self)
  File "/share/apps/software/Core/Anaconda3/2018.12/lib/python3.7/pickle.py", line 1104, in load_proto
    raise ValueError("unsupported pickle protocol: %d" % proto)
ValueError: unsupported pickle protocol: 5

During handling of the above exception, another exception occurred:

Traceback (most recent call last):
  File "/share/apps/software/Core/Anaconda3/2018.12/lib/python3.7/site-packages/pandas/io/pickle.py", line 166, in try_read
    return read_wrapper(lambda f: pkl.load(f))
  File "/share/apps/software/Core/Anaconda3/2018.12/lib/python3.7/site-packages/pandas/io/pickle.py", line 149, in read_wrapper
    return func(f)
  File "/share/apps/software/Core/Anaconda3/2018.12/lib/python3.7/site-packages/pandas/io/pickle.py", line 166, in <lambda>
    return read_wrapper(lambda f: pkl.load(f))
ValueError: unsupported pickle protocol: 5

During handling of the above exception, another exception occurred:

Traceback (most recent call last):
  File "/share/apps/software/Core/Anaconda3/2018.12/lib/python3.7/site-packages/pandas/io/pickle.py", line 171, in try_read
    lambda f: pc.load(f, encoding=encoding, compat=False))
  File "/share/apps/software/Core/Anaconda3/2018.12/lib/python3.7/site-packages/pandas/io/pickle.py", line 149, in read_wrapper
    return func(f)
  File "/share/apps/software/Core/Anaconda3/2018.12/lib/python3.7/site-packages/pandas/io/pickle.py", line 171, in <lambda>
    lambda f: pc.load(f, encoding=encoding, compat=False))
  File "/share/apps/software/Core/Anaconda3/2018.12/lib/python3.7/site-packages/pandas/compat/pickle_compat.py", line 212, in load
    return up.load()
  File "/share/apps/software/Core/Anaconda3/2018.12/lib/python3.7/pickle.py", line 1085, in load
    dispatch[key[0]](self)
  File "/share/apps/software/Core/Anaconda3/2018.12/lib/python3.7/pickle.py", line 1104, in load_proto
    raise ValueError("unsupported pickle protocol: %d" % proto)
ValueError: unsupported pickle protocol: 5

During handling of the above exception, another exception occurred:

Traceback (most recent call last):
  File "./src/check_rotation.py", line 108, in <module>
    subhalo_rotation(tng_run, test_name, 99, int(args.subhalo))
  File "./src/check_rotation.py", line 92, in subhalo_rotation
    group_cat = pd.read_pickle(new_cat_path)
  File "/share/apps/software/Core/Anaconda3/2018.12/lib/python3.7/site-packages/pandas/io/pickle.py", line 180, in read_pickle
    return try_read(path, encoding='latin1')
  File "/share/apps/software/Core/Anaconda3/2018.12/lib/python3.7/site-packages/pandas/io/pickle.py", line 175, in try_read
    lambda f: pc.load(f, encoding=encoding, compat=True))
  File "/share/apps/software/Core/Anaconda3/2018.12/lib/python3.7/site-packages/pandas/io/pickle.py", line 149, in read_wrapper
    return func(f)
  File "/share/apps/software/Core/Anaconda3/2018.12/lib/python3.7/site-packages/pandas/io/pickle.py", line 175, in <lambda>
    lambda f: pc.load(f, encoding=encoding, compat=True))
  File "/share/apps/software/Core/Anaconda3/2018.12/lib/python3.7/site-packages/pandas/compat/pickle_compat.py", line 212, in load
    return up.load()
  File "/share/apps/software/Core/Anaconda3/2018.12/lib/python3.7/pickle.py", line 1085, in load
    dispatch[key[0]](self)
  File "/share/apps/software/Core/Anaconda3/2018.12/lib/python3.7/pickle.py", line 1104, in load_proto
    raise ValueError("unsupported pickle protocol: %d" % proto)
ValueError: unsupported pickle protocol: 5
Traceback (most recent call last):
  File "/share/apps/software/Core/Anaconda3/2018.12/lib/python3.7/site-packages/pandas/io/pickle.py", line 166, in try_read
    return read_wrapper(lambda f: pkl.load(f))
  File "/share/apps/software/Core/Anaconda3/2018.12/lib/python3.7/site-packages/pandas/io/pickle.py", line 149, in read_wrapper
    return func(f)
  File "/share/apps/software/Core/Anaconda3/2018.12/lib/python3.7/site-packages/pandas/io/pickle.py", line 166, in <lambda>
    return read_wrapper(lambda f: pkl.load(f))
ValueError: unsupported pickle protocol: 5

During handling of the above exception, another exception occurred:

Traceback (most recent call last):
  File "/share/apps/software/Core/Anaconda3/2018.12/lib/python3.7/site-packages/pandas/io/pickle.py", line 171, in try_read
    lambda f: pc.load(f, encoding=encoding, compat=False))
  File "/share/apps/software/Core/Anaconda3/2018.12/lib/python3.7/site-packages/pandas/io/pickle.py", line 149, in read_wrapper
    return func(f)
  File "/share/apps/software/Core/Anaconda3/2018.12/lib/python3.7/site-packages/pandas/io/pickle.py", line 171, in <lambda>
    lambda f: pc.load(f, encoding=encoding, compat=False))
  File "/share/apps/software/Core/Anaconda3/2018.12/lib/python3.7/site-packages/pandas/compat/pickle_compat.py", line 212, in load
    return up.load()
  File "/share/apps/software/Core/Anaconda3/2018.12/lib/python3.7/pickle.py", line 1085, in load
    dispatch[key[0]](self)
  File "/share/apps/software/Core/Anaconda3/2018.12/lib/python3.7/pickle.py", line 1104, in load_proto
    raise ValueError("unsupported pickle protocol: %d" % proto)
ValueError: unsupported pickle protocol: 5

During handling of the above exception, another exception occurred:

Traceback (most recent call last):
  File "/share/apps/software/Core/Anaconda3/2018.12/lib/python3.7/site-packages/pandas/io/pickle.py", line 177, in read_pickle
    return try_read(path)
  File "/share/apps/software/Core/Anaconda3/2018.12/lib/python3.7/site-packages/pandas/io/pickle.py", line 175, in try_read
    lambda f: pc.load(f, encoding=encoding, compat=True))
  File "/share/apps/software/Core/Anaconda3/2018.12/lib/python3.7/site-packages/pandas/io/pickle.py", line 149, in read_wrapper
    return func(f)
  File "/share/apps/software/Core/Anaconda3/2018.12/lib/python3.7/site-packages/pandas/io/pickle.py", line 175, in <lambda>
    lambda f: pc.load(f, encoding=encoding, compat=True))
  File "/share/apps/software/Core/Anaconda3/2018.12/lib/python3.7/site-packages/pandas/compat/pickle_compat.py", line 212, in load
    return up.load()
  File "/share/apps/software/Core/Anaconda3/2018.12/lib/python3.7/pickle.py", line 1085, in load
    dispatch[key[0]](self)
  File "/share/apps/software/Core/Anaconda3/2018.12/lib/python3.7/pickle.py", line 1104, in load_proto
    raise ValueError("unsupported pickle protocol: %d" % proto)
ValueError: unsupported pickle protocol: 5

During handling of the above exception, another exception occurred:

Traceback (most recent call last):
  File "/share/apps/software/Core/Anaconda3/2018.12/lib/python3.7/site-packages/pandas/io/pickle.py", line 166, in try_read
    return read_wrapper(lambda f: pkl.load(f))
  File "/share/apps/software/Core/Anaconda3/2018.12/lib/python3.7/site-packages/pandas/io/pickle.py", line 149, in read_wrapper
    return func(f)
  File "/share/apps/software/Core/Anaconda3/2018.12/lib/python3.7/site-packages/pandas/io/pickle.py", line 166, in <lambda>
    return read_wrapper(lambda f: pkl.load(f))
ValueError: unsupported pickle protocol: 5

During handling of the above exception, another exception occurred:

Traceback (most recent call last):
  File "/share/apps/software/Core/Anaconda3/2018.12/lib/python3.7/site-packages/pandas/io/pickle.py", line 171, in try_read
    lambda f: pc.load(f, encoding=encoding, compat=False))
  File "/share/apps/software/Core/Anaconda3/2018.12/lib/python3.7/site-packages/pandas/io/pickle.py", line 149, in read_wrapper
    return func(f)
  File "/share/apps/software/Core/Anaconda3/2018.12/lib/python3.7/site-packages/pandas/io/pickle.py", line 171, in <lambda>
    lambda f: pc.load(f, encoding=encoding, compat=False))
  File "/share/apps/software/Core/Anaconda3/2018.12/lib/python3.7/site-packages/pandas/compat/pickle_compat.py", line 212, in load
    return up.load()
  File "/share/apps/software/Core/Anaconda3/2018.12/lib/python3.7/pickle.py", line 1085, in load
    dispatch[key[0]](self)
  File "/share/apps/software/Core/Anaconda3/2018.12/lib/python3.7/pickle.py", line 1104, in load_proto
    raise ValueError("unsupported pickle protocol: %d" % proto)
ValueError: unsupported pickle protocol: 5

During handling of the above exception, another exception occurred:

Traceback (most recent call last):
  File "./src/check_rotation.py", line 108, in <module>
    subhalo_rotation(tng_run, test_name, 99, int(args.subhalo))
  File "./src/check_rotation.py", line 92, in subhalo_rotation
    group_cat = pd.read_pickle(new_cat_path)
  File "/share/apps/software/Core/Anaconda3/2018.12/lib/python3.7/site-packages/pandas/io/pickle.py", line 180, in read_pickle
    return try_read(path, encoding='latin1')
  File "/share/apps/software/Core/Anaconda3/2018.12/lib/python3.7/site-packages/pandas/io/pickle.py", line 175, in try_read
    lambda f: pc.load(f, encoding=encoding, compat=True))
  File "/share/apps/software/Core/Anaconda3/2018.12/lib/python3.7/site-packages/pandas/io/pickle.py", line 149, in read_wrapper
    return func(f)
  File "/share/apps/software/Core/Anaconda3/2018.12/lib/python3.7/site-packages/pandas/io/pickle.py", line 175, in <lambda>
    lambda f: pc.load(f, encoding=encoding, compat=True))
  File "/share/apps/software/Core/Anaconda3/2018.12/lib/python3.7/site-packages/pandas/compat/pickle_compat.py", line 212, in load
    return up.load()
  File "/share/apps/software/Core/Anaconda3/2018.12/lib/python3.7/pickle.py", line 1085, in load
    dispatch[key[0]](self)
  File "/share/apps/software/Core/Anaconda3/2018.12/lib/python3.7/pickle.py", line 1104, in load_proto
    raise ValueError("unsupported pickle protocol: %d" % proto)
ValueError: unsupported pickle protocol: 5
